Workbook

Sheet Skyrim
A1: место | B1: X | C1: Y | D1: земля Z | E1: превышение | F1: снег | G1: регион (игра) | H1: защита | I1: равновесие | J1: T, градусы
A2: Ferry Drop off Marker | B2: -150233 | C2: 121670 | D2: -13939 | E2: -687 | F2: 0.05 | G2: Coast | J2: =IFERROR(12-(1-I2+VLOOKUP(H2,Справка!$A$2:$B$7,2,FALSE)/100)/0.055,"")
A3: Аванчнзел | B3: 122073 | C3: -107290 | D3: 13172 | E3: -4523 | F3: 0 | G3: FallForest | J3: =IFERROR(12-(1-I3+VLOOKUP(H3,Справка!$A$2:$B$7,2,FALSE)/100)/0.055,"")
A4: Айварстед | B4: 76375 | C4: -64263 | D4: 10816 | E4: -3697 | F4: 0 | G4: FallForest | H4: 4 слота, без резиста | I4: 0.75 | J4: =IFERROR(12-(1-I4+VLOOKUP(H4,Справка!$A$2:$B$7,2,FALSE)/100)/0.055,"") -> -3.2145455
A5: Алтарь Рожденного Небом | B5: -5305 | C5: 48249 | D5: 332 | E5: 4221 | F5: 0.96 | G5: Snow | H5: 4 слота, резист 100% | I5: 0.75 | J5: =IFERROR(12-(1-I5+VLOOKUP(H5,Справка!$A$2:$B$7,2,FALSE)/100)/0.055,"") -> -18.087273
A6: Альфтанд | B6: 78347 | C6: 77409 | D6: -4621 | E6: -1061 | F6: 1 | G6: Snow | J6: =IFERROR(12-(1-I6+VLOOKUP(H6,Справка!$A$2:$B$7,2,FALSE)/100)/0.055,"")
A7: Ангарвунд | B7: 113491 | C7: -97167 | D7: 13467 | E7: -2521 | F7: 0 | G7: FallForest | J7: =IFERROR(12-(1-I7+VLOOKUP(H7,Справка!$A$2:$B$7,2,FALSE)/100)/0.055,"")
A8: Ансилвунд | B8: 174572 | C8: -35183 | D8: -74 | E8: -2468 | F8: 0.2 | G8: Snow | J8: =IFERROR(12-(1-I8+VLOOKUP(H8,Справка!$A$2:$B$7,2,FALSE)/100)/0.055,"")
A9: Аркнтамз | B9: -139019 | C9: -31985 | D9: 894 | E9: -3063 | F9: 0 | G9: Reach | J9: =IFERROR(12-(1-I9+VLOOKUP(H9,Справка!$A$2:$B$7,2,FALSE)/100)/0.055,"")
A10: Арочный перевал | B10: 67923 | C10: 30778 | D10: -7145 | E10: -2093 | F10: 0.84 | G10: Snow | J10: =IFERROR(12-(1-I10+VLOOKUP(H10,Справка!$A$2:$B$7,2,FALSE)/100)/0.055,"")
A11: Балкон замка Волкихар | B11: -168932 | C11: 149155 | D11: -15429 | E11: 731 | F11: 0 | G11: - | J11: =IFERROR(12-(1-I11+VLOOKUP(H11,Справка!$A$2:$B$7,2,FALSE)/100)/0.055,"")
A12: Башни Валтейм | B12: 74450 | C12: -1044 | D12: -5200 | E12: -2971 | F12: 0 | G12: Tundra | J12: =IFERROR(12-(1-I12+VLOOKUP(H12,Справка!$A$2:$B$7,2,FALSE)/100)/0.055,"")
A13: Башня Баннермист | B13: -57305 | C13: -62109 | D13: 908 | E13: 840 | F13: 0 | G13: PineForest | J13: =IFERROR(12-(1-I13+VLOOKUP(H13,Справка!$A$2:$B$7,2,FALSE)/100)/0.055,"")
A14: Башня Белая Сосна | B14: -142901 | C14: 99301 | D14: -4568 | E14: 3216 | F14: 0.98 | G14: Mountains | J14: =IFERROR(12-(1-I14+VLOOKUP(H14,Справка!$A$2:$B$7,2,FALSE)/100)/0.055,"")
A15: Башня Кредлстоун | B15: -99713 | C15: -33861 | D15: 2528 | E15: 1406 | F15: 0 | G15: Reach | J15: =IFERROR(12-(1-I15+VLOOKUP(H15,Справка!$A$2:$B$7,2,FALSE)/100)/0.055,"")
A16: Башня Мзарк | B16: 25834 | C16: 45696 | D16: -4949 | E16: 641 | F16: 0.88 | G16: Snow | J16: =IFERROR(12-(1-I16+VLOOKUP(H16,Справка!$A$2:$B$7,2,FALSE)/100)/0.055,"")
A17: Башня Светотьмы | B17: 149285 | C17: -115997 | D17: 12250 | E17: -3054 | F17: 0 | G17: DarklightTower | J17: =IFERROR(12-(1-I17+VLOOKUP(H17,Справка!$A$2:$B$7,2,FALSE)/100)/0.055,"")
... A24: Вайтран - Имперский лагерь | B24: -62784 | C24: 2444 | D24: -5448 | E24: -109 | F24: 0 | G24: Tundra | J24: =IFERROR(12-(1-I24+VLOOKUP(H24,Справка!$A$2:$B$7,2,FALSE)/100)/0.055,"")
A25: Вайтран - Конюшни | B25: 18313 | C25: -10665 | D25: -4616 | E25: -672 | F25: 0 | G25: Tundra | H25: 4 слота, без резиста | I25: 0.85 | J25: =IFERROR(12-(1-I25+VLOOKUP(H25,Справка!$A$2:$B$7,2,FALSE)/100)/0.055,"") -> -1.3963636
A26: Вайтран - Лагерь Братьев Бури | B26: 51980 | C26: -16247 | D26: -697 | E26: -2295 | F26: 0.12 | G26: Tundra | J26: =IFERROR(12-(1-I26+VLOOKUP(H26,Справка!$A$2:$B$7,2,FALSE)/100)/0.055,"")
A27: Валтум | B27: -114984 | C27: -31214 | D27: 28 | E27: -1267 | F27: 0 | G27: Reach | J27: =IFERROR(12-(1-I27+VLOOKUP(H27,Справка!$A$2:$B$7,2,FALSE)/100)/0.055,"")
A28: Ведьмин оплот | B28: -173318 | C28: -17116 | D28: 3265 | E28: -3414 | F28: 0 | G28: Reach | J28: =IFERROR(12-(1-I28+VLOOKUP(H28,Справка!$A$2:$B$7,2,FALSE)/100)/0.055,"")
A29: Вершина Северный Ветер | B29: 151003 | C29: -53453 | D29: 13176 | E29: 5792 | F29: 0 | G29: PineForest | J29: =IFERROR(12-(1-I29+VLOOKUP(H29,Справка!$A$2:$B$7,2,FALSE)/100)/0.055,"")
A30: Веселая ферма | B30: 166304 | C30: -88702 | D30: 11046 | E30: 768 | F30: 0 | G30: FFRiften | J30: =IFERROR(12-(1-I30+VLOOKUP(H30,Справка!$A$2:$B$7,2,FALSE)/100)/0.055,"")
A31: Ветреный пик | B31: 1482 | C31: -41162 | D31: 4470 | E31: 2436 | F31: 0.98 | G31: Mountains | H31: 4 слота, резист 50% | I31: 0.25 | J31: =IFERROR(12-(1-I31+VLOOKUP(H31,Справка!$A$2:$B$7,2,FALSE)/100)/0.055,"") -> -19.741818
A32: Ветровая Дуга | B32: 66950 | C32: -99471 | D32: 15816 | E32: -3754 | F32: 0.98 | G32: Mountains | H32: 4 слота, резист 25% | I32: 0.7 | J32: =IFERROR(12-(1-I32+VLOOKUP(H32,Справка!$A$2:$B$7,2,FALSE)/100)/0.055,"") -> -7.8418182
A33: Вечерняя пещера | B33: -154519 | C33: 72471 | D33: -5248 | E33: -105 | F33: 0.51 | G33: Reach | J33: =IFERROR(12-(1-I33+VLOOKUP(H33,Справка!$A$2:$B$7,2,FALSE)/100)/0.055,"")
A34: Вечнозеленая роща | B34: -51018 | C34: -67845 | D34: -1046 | E34: -644 | F34: 0 | G34: PineForest | J34: =IFERROR(12-(1-I34+VLOOKUP(H34,Справка!$A$2:$B$7,2,FALSE)/100)/0.055,"")
A35: Виндхельм - Военный лагерь | B35: 147889 | C35: 25487 | D35: -10113 | E35: -874 | F35: 0.93 | G35: Snow | J35: =IFERROR(12-(1-I35+VLOOKUP(H35,Справка!$A$2:$B$7,2,FALSE)/100)/0.055,"")
A36: Виндхельм - Военный лагерь | B36: 147993 | C36: 25449 | D36: -10117 | E36: -879 | F36: 0.93 | G36: Snow | J36: =IFERROR(12-(1-I36+VLOOKUP(H36,Справка!$A$2:$B$7,2,FALSE)/100)/0.055,"")
A37: Виндхельм - Конюшни | B37: 135886 | C37: 26101 | D37: -12736 | E37: -1213 | F37: 1 | G37: Snow | H37: 4 слота, резист 50% | I37: 0.85 | J37: =IFERROR(12-(1-I37+VLOOKUP(H37,Справка!$A$2:$B$7,2,FALSE)/100)/0.055,"") -> -8.8327273
A38: Винтерхолд | B38: 109208 | C38: 102864 | D38: -9031 | E38: 1980 | F38: 0.99 | G38: Winterhold | H38: 4 слота, резист 50% | I38: 0.75 | J38: =IFERROR(12-(1-I38+VLOOKUP(H38,Справка!$A$2:$B$7,2,FALSE)/100)/0.055,"") -> -10.650909
A39: Винтерхолд - Имперский лагерь | B39: 51948 | C39: 95472 | D39: -6928 | E39: 2272 | F39: 0.99 | G39: Snow | J39: =IFERROR(12-(1-I39+VLOOKUP(H39,Справка!$A$2:$B$7,2,FALSE)/100)/0.055,"")
A40: Винтерхолд - Лагерь Братьев Бури | B40: 145204 | C40: 55116 | D40: -11394 | E40: -309 | F40: 0.99 | G40: Snow | J40: =IFERROR(12-(1-I40+VLOOKUP(H40,Справка!$A$2:$B$7,2,FALSE)/100)/0.055,"")
A41: Висельная скала | B41: 100514 | C41: 5878 | D41: -8114 | E41: -566 | F41: 0.4 | G41: Snow | J41: =IFERROR(12-(1-I41+VLOOKUP(H41,Справка!$A$2:$B$7,2,FALSE)/100)/0.055,"")
A42: Водоем Холодный Ветер | B42: 1539 | C42: 1306 | D42: -5930 | E42: -461 | F42: 0 | G42: Tundra | J42: =IFERROR(12-(1-I42+VLOOKUP(H42,Справка!$A$2:$B$7,2,FALSE)/100)/0.055,"")
A43: Волундруд | B43: 10419 | C43: 31080 | D43: -1536 | E43: 875 | F43: 0.7 | G43: Snow | J43: =IFERROR(12-(1-I43+VLOOKUP(H43,Справка!$A$2:$B$7,2,FALSE)/100)/0.055,"")
A44: Вольскигге | B44: -130324 | C44: 92287 | D44: -7063 | E44: -656 | F44: 0.3 | G44: Tundra | J44: =IFERROR(12-(1-I44+VLOOKUP(H44,Справка!$A$2:$B$7,2,FALSE)/100)/0.055,"")
A45: Воронья нора | B45: -91591 | C45: 126460 | D45: -13891 | E45: -3870 | F45: 0.26 | G45: Coast | J45: =IFERROR(12-(1-I45+VLOOKUP(H45,Справка!$A$2:$B$7,2,FALSE)/100)/0.055,"")
A46: Высокий Хротгар | B46: 52071 | C46: -36267 | D46: 22839 | E46: 7758 | F46: 1 | G46: Mountains | H46: 4 слота, резист 50% | I46: 0.15 | J46: =IFERROR(12-(1-I46+VLOOKUP(H46,Справка!$A$2:$B$7,2,FALSE)/100)/0.055,"") -> -21.56
...

Sheet Solstheim
A1: место | B1: X | C1: Y | D1: земля Z | E1: превышение | F1: снег | G1: регион (игра) | H1: защита | I1: равновесие | J1: T, градусы
A2: Проход Моэсринг | B2: 43062 | C2: 68108 | D2: 12387 | E2: 4902 | F2: 1 | G2: DLC2SolstheimMtns | H2: 4 слота, резист 100% | I2: 0.3 | J2: =IFERROR(12-(1-I2+VLOOKUP(H2,Справка!$A$2:$B$7,2,FALSE)/100)/0.055,"") -> -26.269091
A3: Гора Моэсринг | B3: 42318 | C3: 64114 | D3: 12265 | E3: 5049 | F3: 0.84 | G3: DLC2SolstheimMtns | J3: =IFERROR(12-(1-I3+VLOOKUP(H3,Справка!$A$2:$B$7,2,FALSE)/100)/0.055,"")
A4: Пик Фрукт | B4: 40331 | C4: 82291 | D4: 10342 | E4: 5736 | F4: 0.96 | G4: DLC2SolstheimSnow | J4: =IFERROR(12-(1-I4+VLOOKUP(H4,Справка!$A$2:$B$7,2,FALSE)/100)/0.055,"")
A5: Курган Хротмунда | B5: 43520 | C5: 75284 | D5: 9649 | E5: 2701 | F5: 1 | G5: DLC2SolstheimSnow | J5: =IFERROR(12-(1-I5+VLOOKUP(H5,Справка!$A$2:$B$7,2,FALSE)/100)/0.055,"")
A6: Храм Мирака | B6: 56313 | C6: 59653 | D6: 9132 | E6: 2825 | F6: 0.86 | G6: DLC2SolstheimSnow | J6: =IFERROR(12-(1-I6+VLOOKUP(H6,Справка!$A$2:$B$7,2,FALSE)/100)/0.055,"")
A7: Пик Мортраг | B7: 33517 | C7: 82146 | D7: 8902 | E7: 4661 | F7: 1 | G7: DLC2SolstheimSnow | J7: =IFERROR(12-(1-I7+VLOOKUP(H7,Справка!$A$2:$B$7,2,FALSE)/100)/0.055,"")
A8: Заснеженные руины | B8: 50727 | C8: 69890 | D8: 8800 | E8: 2120 | F8: 0.63 | G8: DLC2SolstheimMtns | J8: =IFERROR(12-(1-I8+VLOOKUP(H8,Справка!$A$2:$B$7,2,FALSE)/100)/0.055,"")
A9: Курган Белого Хребта | B9: 33692 | C9: 76147 | D9: 8536 | E9: 2204 | F9: 0.91 | G9: DLC2SolstheimSnow | J9: =IFERROR(12-(1-I9+VLOOKUP(H9,Справка!$A$2:$B$7,2,FALSE)/100)/0.055,"")
A10: Фалбтарз | B10: 30921 | C10: 65460 | D10: 8228 | E10: 3033 | F10: 0.98 | G10: DLC2SolstheimMtns | J10: =IFERROR(12-(1-I10+VLOOKUP(H10,Справка!$A$2:$B$7,2,FALSE)/100)/0.055,"")
A11: Бенконгерик | B11: 48814 | C11: 80247 | D11: 7988 | E11: 2436 | F11: 0.98 | G11: DLC2SolstheimSnow | J11: =IFERROR(12-(1-I11+VLOOKUP(H11,Справка!$A$2:$B$7,2,FALSE)/100)/0.055,"")
A12: Пик Хвиткальд | B12: 32748 | C12: 53603 | D12: 7978 | E12: 3847 | F12: 0.88 | G12: DLC2SolstheimMtns | J12: =IFERROR(12-(1-I12+VLOOKUP(H12,Справка!$A$2:$B$7,2,FALSE)/100)/0.055,"")
A13: Застава Сиринга | B13: 42884 | C13: 83949 | D13: 7680 | E13: 3077 | F13: 1 | G13: DLC2SolstheimSnow | H13: 4 слота, резист 100% | I13: 0.5 | J13: =IFERROR(12-(1-I13+VLOOKUP(H13,Справка!$A$2:$B$7,2,FALSE)/100)/0.055,"") -> -22.632727
A14: Источник сталгрима | B14: 29071 | C14: 78772 | D14: 7464 | E14: 2899 | F14: 1 | G14: DLC2SolstheimMtns | J14: =IFERROR(12-(1-I14+VLOOKUP(H14,Справка!$A$2:$B$7,2,FALSE)/100)/0.055,"")
A15: Алтарь Тронда | B15: 48656 | C15: 59824 | D15: 7304 | E15: 413 | F15: 1 | G15: DLC2SolstheimMtns | J15: =IFERROR(12-(1-I15+VLOOKUP(H15,Справка!$A$2:$B$7,2,FALSE)/100)/0.055,"")
A16: Утес Морозной Луны | B16: 41569 | C16: 57139 | D16: 6830 | E16: 605 | F16: 0.96 | G16: DLC2SolstheimMtns | J16: =IFERROR(12-(1-I16+VLOOKUP(H16,Справка!$A$2:$B$7,2,FALSE)/100)/0.055,"")
A17: Камень Зверя | B17: 62811 | C17: 58376 | D17: 6508 | E17: 1489 | F17: 0.97 | G17: DLC2SolstheimSnow | J17: =IFERROR(12-(1-I17+VLOOKUP(H17,Справка!$A$2:$B$7,2,FALSE)/100)/0.055,"")
A18: Руины замка Карстаг | B18: 33312 | C18: 89920 | D18: 6279 | E18: 3342 | F18: 1 | G18: DLC2SolstheimSnowHeavy | J18: =IFERROR(12-(1-I18+VLOOKUP(H18,Справка!$A$2:$B$7,2,FALSE)/100)/0.055,"")
A19: Заброшенный постоялый двор | B19: 35747 | C19: 52080 | D19: 5832 | E19: 1453 | F19: 0.78 | G19: VolcanicAsh02 | J19: =IFERROR(12-(1-I19+VLOOKUP(H19,Справка!$A$2:$B$7,2,FALSE)/100)/0.055,"")
A20: Гробница Валока | B20: 70722 | C20: 51191 | D20: 5644 | E20: 2456 | F20: 0.06 | G20: VolcanicAsh02 | J20: =IFERROR(12-(1-I20+VLOOKUP(H20,Справка!$A$2:$B$7,2,FALSE)/100)/0.055,"")
A21: Медовый зал Тирска | B21: 67274 | C21: 58587 | D21: 5365 | E21: 1198 | F21: 0.99 | G21: DLC2SolstheimSnow | J21: =IFERROR(12-(1-I21+VLOOKUP(H21,Справка!$A$2:$B$7,2,FALSE)/100)/0.055,"")
A22: Шахта Сломанный Клык | B22: 22621 | C22: 80019 | D22: 5183 | E22: 3069 | F22: 0.99 | G22: DLC2SolstheimMtns | H22: 4 слота, резист 100% | I22: 0.5 | J22: =IFERROR(12-(1-I22+VLOOKUP(H22,Справка!$A$2:$B$7,2,FALSE)/100)/0.055,"") -> -22.632727
A23: Пещеры замка Карстаг | B23: 36832 | C23: 88320 | D23: 4596 | E23: 1659 | F23: 1 | G23: DLC2SolstheimSnow | J23: =IFERROR(12-(1-I23+VLOOKUP(H23,Справка!$A$2:$B$7,2,FALSE)/100)/0.055,"")
A24: Вершинная башня | B24: 49334 | C24: 38004 | D24: 4527 | E24: 1056 | F24: 0 | G24: VolcanicAsh01 | H24: 4 слота, резист 50% | I24: 0.75 | J24: =IFERROR(12-(1-I24+VLOOKUP(H24,Справка!$A$2:$B$7,2,FALSE)/100)/0.055,"") -> -10.650909
A25: Старый торговый пост | B25: 57695 | C25: 43972 | D25: 4137 | E25: 170 | F25: 0 | G25: VolcanicAsh01 | J25: =IFERROR(12-(1-I25+VLOOKUP(H25,Справка!$A$2:$B$7,2,FALSE)/100)/0.055,"")
A26: Верховье Харстрада | B26: 54028 | C26: 77963 | D26: 3743 | E26: -636 | F26: 0.82 | G26: DLC2SolstheimSnow | J26: =IFERROR(12-(1-I26+VLOOKUP(H26,Справка!$A$2:$B$7,2,FALSE)/100)/0.055,"")
A27: Роща Бродира | B27: 43753 | C27: 43975 | D27: 3617 | E27: -247 | F27: 0 | G27: VolcanicAsh01 | J27: =IFERROR(12-(1-I27+VLOOKUP(H27,Справка!$A$2:$B$7,2,FALSE)/100)/0.055,"")
A28: Пепельная крепость | B28: 66672 | C28: 41649 | D28: 3558 | E28: 485 | F28: 0 | G28: VolcanicAsh01 | J28: =IFERROR(12-(1-I28+VLOOKUP(H28,Справка!$A$2:$B$7,2,FALSE)/100)/0.055,"")
A29: Кагрумез | B29: 55880 | C29: 50199 | D29: 3304 | E29: -2261 | F29: 0.19 | G29: VolcanicAsh02 | H29: 4 слота, резист 50% | I29: 0.75 | J29: =IFERROR(12-(1-I29+VLOOKUP(H29,Справка!$A$2:$B$7,2,FALSE)/100)/0.055,"") -> -10.650909
A30: Камень Воды | B30: 21588 | C30: 64459 | D30: 3092 | E30: 304 | F30: 0.43 | G30: DLC2SolstheimMtns | J30: =IFERROR(12-(1-I30+VLOOKUP(H30,Справка!$A$2:$B$7,2,FALSE)/100)/0.055,"")
A31: Деревня Скаалов | B31: 73452 | C31: 70790 | D31: 2865 | E31: 687 | F31: 0.98 | G31: SkaalVillage01 | H31: 4 слота, резист 75% | I31: 0.75 | J31: =IFERROR(12-(1-I31+VLOOKUP(H31,Справка!$A$2:$B$7,2,FALSE)/100)/0.055,"") -> -14.369091
A32: Душная шахта | B32: 25738 | C32: 55271 | D32: 2654 | E32: -470 | F32: 0.17 | G32: DLC2SolstheimMtns | J32: =IFERROR(12-(1-I32+VLOOKUP(H32,Справка!$A$2:$B$7,2,FALSE)/100)/0.055,"")
A33: Камень Ветра | B33: 63355 | C33: 75109 | D33: 2160 | E33: -1447 | F33: 0.81 | G33: DLC2SolstheimSnow | J33: =IFERROR(12-(1-I33+VLOOKUP(H33,Справка!$A$2:$B$7,2,FALSE)/100)/0.055,"")
A34: Тель-Митрин | B34: 75484 | C34: 23835 | D34: 1865 | E34: 2603 | F34: 0 | G34: VolcanicAsh01 | H34: 4 слота, резист 25% | I34: 0.85 | J34: =IFERROR(12-(1-I34+VLOOKUP(H34,Справка!$A$2:$B$7,2,FALSE)/100)/0.055,"") -> -5.1145455
A35: Форт Морозного Мотылька | B35: 52459 | C35: 23940 | D35: 1654 | E35: 887 | F35: 0 | G35: VolcanicAsh01 | H35: 4 слота, резист 25% | I35: 0.75 | J35: =IFERROR(12-(1-I35+VLOOKUP(H35,Справка!$A$2:$B$7,2,FALSE)/100)/0.055,"") -> -6.9327273
A36: Курган Колбьорн | B36: 38040 | C36: 25760 | D36: 1338 | E36: 303 | F36: 0 | G36: VolcanicAsh01 | J36: =IFERROR(12-(1-I36+VLOOKUP(H36,Справка!$A$2:$B$7,2,FALSE)/100)/0.055,"")
A37: Камень Солнца | B37: 72854 | C37: 34655 | D37: 1317 | E37: -131 | F37: 0 | G37: VolcanicAsh01 | J37: =IFERROR(12-(1-I37+VLOOKUP(H37,Справка!$A$2:$B$7,2,FALSE)/100)/0.055,"")
A38: Дом Хродульфа | B38: 43976 | C38: 19472 | D38: 1201 | E38: 1286 | F38: 0 | G38: VolcanicAsh01 | J38: =IFERROR(12-(1-I38+VLOOKUP(H38,Справка!$A$2:$B$7,2,FALSE)/100)/0.055,"")
A39: Остров Хоркеров | B39: 88252 | C39: 70979 | D39: 726 | E39: 1599 | F39: 0.53 | G39: DLC2SolstheimSnowHeavy | J39: =IFERROR(12-(1-I39+VLOOKUP(H39,Справка!$A$2:$B$7,2,FALSE)/100)/0.055,"")
A40: Пристанище Буйольд | B40: 80276 | C40: 58550 | D40: 687 | E40: -730 | F40: 0.03 | G40: DLC2SolstheimSnow | J40: =IFERROR(12-(1-I40+VLOOKUP(H40,Справка!$A$2:$B$7,2,FALSE)/100)/0.055,"")
...

Sheet Справка
A1: защита | B1: warmth | D1: Как это считается
A2: голым | B2: 0 | D2: warmth = слоты x 14.67 + резист% x 0.818
A3: 4 слота, без резиста | B3: 58.68 | D3: chill = max(0, 12 - температура)
A4: 4 слота, резист 25% | B4: 79.13 | D4: load = chill x 0.055 - warmth x 0.010 (сухо, без огня)
A5: 4 слота, резист 50% | B5: 99.58 | D5: шкала стремится к 1 - load
A6: 4 слота, резист 75% | B6: 120.03
A7: 4 слота, резист 100% | B7: 140.48 | D7: обратно: температура = 12 - (1 - равновесие + warmth/100) / 0.055
D9: Равновесие можно ставить БОЛЬШЕ 1: это значит 'полная с запасом'.
D10: Ровно 1.0 значит 'полная, но без запаса'.
D12: Условия всюду одни: день, ясно, сухо, рядом нет огня.
D14: Лист на мир. Заполняй любую строку - карта строится по всем, где
D15: есть и защита, и равновесие. Перегенерация ответы не затирает:
D16: они переносятся ПО КООРДИНАТАМ, с любого листа.
D18: Имена берутся из строковых таблиц игры: у Скайрима из тех, что
D19: кладёт сборка, у DLC - прямо из Skyrim - Interface.bsa. Если имя
D20: не нашлось, строка названа по типу маркера и координатам.
D21: Переименовывай как угодно: ответ привязан к месту, а не к
D22: подписи, и от переименования не теряется.
